Traceback (most recent call last):
  File "/home/gt1188/Semi-Supervised-Object-Detection/norm_para.py", line 52, in <module>
    main()
  File "/home/gt1188/Semi-Supervised-Object-Detection/norm_para.py", line 37, in main
    for data in data_loader:
  File "/ext3/miniconda3/lib/python3.9/site-packages/torch/utils/data/dataloader.py", line 530, in __next__
    data = self._next_data()
  File "/ext3/miniconda3/lib/python3.9/site-packages/torch/utils/data/dataloader.py", line 1224, in _next_data
    return self._process_data(data)
  File "/ext3/miniconda3/lib/python3.9/site-packages/torch/utils/data/dataloader.py", line 1250, in _process_data
    data.reraise()
  File "/ext3/miniconda3/lib/python3.9/site-packages/torch/_utils.py", line 457, in reraise
    raise exception
OSError: Caught OSError in DataLoader worker process 1.
Original Traceback (most recent call last):
  File "/ext3/miniconda3/lib/python3.9/site-packages/torch/utils/data/_utils/worker.py", line 287, in _worker_loop
    data = fetcher.fetch(index)
  File "/ext3/miniconda3/lib/python3.9/site-packages/torch/utils/data/_utils/fetch.py", line 49, in fetch
    data = [self.dataset[idx] for idx in possibly_batched_index]
  File "/ext3/miniconda3/lib/python3.9/site-packages/torch/utils/data/_utils/fetch.py", line 49, in <listcomp>
    data = [self.dataset[idx] for idx in possibly_batched_index]
  File "/home/gt1188/Semi-Supervised-Object-Detection/norm_para.py", line 24, in __getitem__
    img = Image.open(f).convert('RGB')
  File "/ext3/miniconda3/lib/python3.9/site-packages/PIL/Image.py", line 2962, in open
    prefix = fp.read(16)
OSError: [Errno 5] Input/output error

